Workbook

Sheet Sheep
A1: id | B1: BATT tag | C1: gen | D1: gen | E1: other tag | F1: purchase date | G1: purchase price | H1: sale date | I1: sale $ | J1: born | L1: sire | M1: dam | N1: dam tag | O1: lambs | P1: lambs this year | Q1: lamb age (days) | R1: cull | S1: Desc | T1: Prohibit Ewes 7/30/2025 | U1: market lamb Valbazen+CD&T 7/1/2025 | V1: gary janes 5/10/2025 | W1: prohibit 4/22/2025 | X1: cd&t 4/22/2025 | Y1: 2025/3/16 prohibit ewes (not lambed yet) | Z1: 2024/9/3 wormer | AA1: 2024/4/23 vax | AB1: event 1 | AC1: event 2 | AE1: 44511 | AF1: 44519 | AG1: 11/19 weight | AH1: 11/19 sale | AJ1: vaccine 12/26/2021
A2: 1 | B2: 257 | C2: original flock | D2: 1601 | E2: 257 | F2: 42694 | G2: 250 | H2: 44108 | J2: 42370 | K2: f | N2: =xlookup(M2,A:A,B:B) -> #N/A | O2: =countif(M:M,A2) -> 7 | Q2: =today()-xlookup(A2,M:M,J:J,"",0,-1) -> 2150 | R2: =if("m"=K2,"X",if(or(countif(Cull!A:A,B:B)>0,"X"= XLOOKUP(M:M,A:A,R:R)),"X","")) -> #REF! | S2: cinnimon | AB2: 2 healthy lambs | AC2: 2 brown white head spot (7&8) & 1 still born | AD2: found dead in field (acidiosis? Ate a bunch of corn.)
A3: 2 | B3: 258 | C3: original flock | D3: 1602 | E3: 258 | F3: 42694 | G3: 250 | H3: 44520 | I3: 187 | J3: 42370 | K3: f | N3: =xlookup(M3,A:A,B:B) -> #N/A | O3: =countif(M:M,A3) -> 7 | Q3: =today()-xlookup(A3,M:M,J:J,"",0,-1) -> 1867 | R3: =if("m"=K3,"X",if(or(countif(Cull!A:A,B:B)>0,"X"= XLOOKUP(M:M,A:A,R:R)),"X","")) -> #REF! | S3: cinnimon | AB3: 2 healthy lambs | AH3: Janes
A4: 3 | B4: 255 | C4: original flock | D4: 1539 | E4: white | F4: 42694 | G4: 250 | H4: 45450 | J4: 42370 | K4: f | N4: =xlookup(M4,A:A,B:B) -> #N/A | O4: =countif(M:M,A4) -> 11 | Q4: =today()-xlookup(A4,M:M,J:J,"",0,-1) -> 692 | R4: =if("m"=K4,"X",if(or(countif(Cull!A:A,B:B)>0,"X"= XLOOKUP(M:M,A:A,R:R)),"X","")) -> #REF! | S4: White | AA4: v | AB4: Single dead Lamb. induced by goat butt? | AC4: (2 white females, 9&10) | AD4: 4/17/2020 got the squirts | AJ4: x
A5: 4 | B5: 000002 | C5: 1 | D5: 000002 | H5: 45826 | J5: 42797 | K5: f | M5: 1 | N5: =xlookup(M5,A:A,B:B) -> 257 | O5: =countif(M:M,A5) -> 8 | P5: =COUNTIFS(N:N,B5,J:J,">1/1/2025") -> 1 | Q5: =today()-xlookup(A5,M:M,J:J,"",0,-1) -> 261 | R5: =if(if("m"=K5,true,countif(Cull!A:A,B:B)>0),"X","") -> #REF! | S5: brown | Z5: x | AA5: c | AE5: weights? | AJ5: x
A6: 5 | B6: 000005 | C6: 1 | D6: 000005 | H6: 43092 | I6: 125 | J6: 42797 | K6: m | M6: 2 | N6: =xlookup(M6,A:A,B:B) -> 258 | O6: =countif(M:M,A6) -> 0 | P6: =COUNTIFS(N:N,B6,J:J,">1/1/2025") -> 0 | Q6: =today()-xlookup(A6,M:M,J:J,"",0,-1) -> 46012 | R6: =if(if("m"=K6,true,countif(Cull!A:A,B:B)>0),"X","") -> X | S6: speckled
A7: 6 | C7: 1 | F7: 43040 | G7: 200 | H7: 43561 | I7: 104 | J7: 42795 | K7: m | N7: =xlookup(M7,A:A,B:B) -> #N/A | O7: =countif(M:M,A7) -> 0 | P7: =COUNTIFS(N:N,B7,J:J,">1/1/2025") -> 0 | R7: =if("m"=K7,"X",if(or(countif(Cull!A:A,B:B)>0,"X"= XLOOKUP(M:M,A:A,R:R)),"X","")) -> X | S7: brown
A8: 7 | C8: 2 | D8: 1 | H8: 43561 | I8: 155 | J8: 43190 | K8: m | L8: 6 | M8: 1 | N8: =xlookup(M8,A:A,B:B) -> 257 | O8: =countif(M:M,A8) -> 0 | P8: =COUNTIFS(N:N,B8,J:J,">1/1/2025") -> 0 | R8: =if("m"=K8,"X",if(or(countif(Cull!A:A,B:B)>0,"X"= XLOOKUP(M:M,A:A,R:R)),"X","")) -> X | S8: brown white spot on head
A9: 8 | C9: 2 | H9: 43274 | J9: 43190 | K9: m | L9: 6 | M9: 1 | N9: =xlookup(M9,A:A,B:B) -> 257 | O9: =countif(M:M,A9) -> 0 | P9: =COUNTIFS(N:N,B9,J:J,">1/1/2025") -> 0 | R9: =if("m"=K9,"X",if(or(countif(Cull!A:A,B:B)>0,"X"= XLOOKUP(M:M,A:A,R:R)),"X","")) -> X | S9: brown white spot on head | AB9: coyote
A10: 9 | B10: 000017 | C10: 2 | D10: 17 | J10: 43198 | K10: f | L10: 6 | M10: 3 | N10: =xlookup(M10,A:A,B:B) -> 255 | O10: =countif(M:M,A10) -> 8 | P10: =COUNTIFS(N:N,B10,J:J,">1/1/2025") -> 2 | Q10: =today()-xlookup(A10,M:M,J:J,"",0,-1) -> 338 | R10: =if(if("m"=K10,true,countif(Cull!A:A,B:B)>0),"X","") -> #REF! | S10: white speckles nose | T10: x | W10: x | Z10: x | AJ10: x
A11: 10 | B11: 1006 | C11: 2 | J11: 43198 | K11: f | L11: 6 | M11: 3 | N11: =xlookup(M11,A:A,B:B) -> 255 | O11: =countif(M:M,A11) -> 8 | P11: =COUNTIFS(N:N,B11,J:J,">1/1/2025") -> 0 | Q11: =today()-xlookup(A11,M:M,J:J,"",0,-1) -> 702 | R11: =if(if("m"=K11,true,countif(Cull!A:A,B:B)>0),"X","") -> #REF! | S11: white speckles, 3/31/2025 swollen jaw; head caught in fence? | W11: x | Z11: x | AA11: c | AB11: 1058? | AC11: retag 1192? | AJ11: x
A12: 11 | C12: 2 | H12: 43210 | J12: 43201 | K12: m | L12: 6 | M12: 4 | N12: =xlookup(M12,A:A,B:B) -> 000002 | O12: =countif(M:M,A12) -> 0 | P12: =COUNTIFS(N:N,B12,J:J,">1/1/2025") -> 0 | R12: {=if("m"=K12,"X",if(or(countif(Cull!A:A,B:B)>0,"X"= XLOOKUP(M:M,A:A,R:R)),"X",""))} -> X | S12: brown white spot on head | AB12: coyote
A13: 12 | B13: 000018 | C13: 2 | D13: 18 | H13: 45826 | J13: 43201 | K13: f | L13: 6 | M13: 4 | N13: =xlookup(M13,A:A,B:B) -> 000002 | O13: =countif(M:M,A13) -> 6 | P13: =COUNTIFS(N:N,B13,J:J,">1/1/2025") -> 1 | Q13: {=today()-xlookup(A13,M:M,J:J,"",0,-1)} -> 314 | R13: =if(if("m"=K13,true,countif(Cull!A:A,B:B)>0),"X","") -> #REF! | S13: all brown, good mom, but singles | W13: x | Z13: x | AA13: v | AJ13: x
A14: 13 | C14: 2 | H14: 43222 | J14: 43213 | K14: m | L14: 6 | M14: 2 | N14: =xlookup(M14,A:A,B:B) -> 258 | O14: =countif(M:M,A14) -> 1 | P14: =COUNTIFS(N:N,B14,J:J,">1/1/2025") -> 0 | R14: =if("m"=K14,"X",if(or(countif(Cull!A:A,B:B)>0,"X"= XLOOKUP(M:M,A:A,R:R)),"X","")) -> X | S14: all brown | AB14: coyote
A15: 14 | C15: 2 | H15: 43222 | J15: 43213 | K15: m | L15: 6 | M15: 2 | N15: =xlookup(M15,A:A,B:B) -> 258 | O15: =countif(M:M,A15) -> 0 | P15: =COUNTIFS(N:N,B15,J:J,">1/1/2025") -> 0 | R15: =if("m"=K15,"X",if(or(countif(Cull!A:A,B:B)>0,"X"= XLOOKUP(M:M,A:A,R:R)),"X","")) -> X | S15: all brown | AB15: coyote
A16: 15 | B16: 000015 | C16: 3 | D16: 15 | H16: 45801 | J16: 43530 | K16: f | L16: 6 | M16: 3 | N16: =xlookup(M16,A:A,B:B) -> 255 | O16: =countif(M:M,A16) -> 7 | P16: =COUNTIFS(N:N,B16,J:J,">1/1/2025") -> 3 | Q16: {=today()-xlookup(A16,M:M,J:J,"",0,-1)} -> 320 | R16: =if(if("m"=K16,true,countif(Cull!A:A,B:B)>0),"X","") -> #REF! | S16: brown collar | W16: x | Z16: x | AA16: v | AJ16: x
A17: 16 | C17: 3 | D17: 16 | H17: 43770 | I17: 100 | J17: 43530 | K17: m | L17: 6 | M17: 3 | N17: =xlookup(M17,A:A,B:B) -> 255 | O17: =countif(M:M,A17) -> 0 | P17: =COUNTIFS(N:N,B17,J:J,">1/1/2025") -> 0 | R17: =if("m"=K17,"X",if(or(countif(Cull!A:A,B:B)>0,"X"= XLOOKUP(M:M,A:A,R:R)),"X","")) -> X | S17: white | AB17: Sold as a teaser to Joe Baldwin
A18: 17 | C18: 3 | D18: 12 | H18: 43670 | J18: 43530 | K18: m | L18: 6 | M18: 2 | N18: =xlookup(M18,A:A,B:B) -> 258 | O18: =countif(M:M,A18) -> 0 | P18: =COUNTIFS(N:N,B18,J:J,">1/1/2025") -> 0 | R18: =if("m"=K18,"X",if(or(countif(Cull!A:A,B:B)>0,"X"= XLOOKUP(M:M,A:A,R:R)),"X","")) -> X | S18: brown white head mark | AB18: overeating?
A19: 18 | C19: 3 | D19: 11 | J19: 43535 | K19: f | L19: 6 | M19: 9 | N19: =xlookup(M19,A:A,B:B) -> 000017 | O19: =countif(M:M,A19) -> 0 | P19: =COUNTIFS(N:N,B19,J:J,">1/1/2025") -> 0 | R19: =if("m"=K19,"X",if(or(countif(Cull!A:A,B:B)>0,"X"= XLOOKUP(M:M,A:A,R:R)),"X","")) -> #REF! | S19: brown | AA19: c | AB19: 1183?
A20: 19 | B20: 000008 | C20: 3 | D20: 8 | J20: 43535 | K20: f | L20: 6 | M20: 10 | N20: =xlookup(M20,A:A,B:B) -> 1006 | O20: =countif(M:M,A20) -> 9 | P20: =COUNTIFS(N:N,B20,J:J,">1/1/2025") -> 2 | Q20: {=today()-xlookup(A20,M:M,J:J,"",0,-1)} -> 319 | R20: =if(if("m"=K20,true,countif(Cull!A:A,B:B)>0),"X","") -> #REF! | S20: brown | T20: x | W20: x | Z20: x | AA20: v | AE20: 104 | AF20: f | AI20: =IF(K20=AF20,"","X") | AJ20: x
A21: 20 | D21: BAG2919 | E21: 2919 | F21: 43531 | G21: 275 | H21: 44521 | I21: trade | J21: 2016 | K21: m | N21: =xlookup(M21,A:A,B:B) -> #N/A | O21: =countif(M:M,A21) -> 0 | P21: =COUNTIFS(N:N,B21,J:J,">1/1/2025") -> 0 | R21: {=if("m"=K21,"X",if(or(countif(Cull!A:A,B:B)>0,"X"= XLOOKUP(M:M,A:A,R:R)),"X",""))} -> X
A22: 21 | B22: 000013 | C22: 3 | D22: 13 | H22: 45801 | J22: 43547 | K22: f | L22: 6 | M22: 1 | N22: =xlookup(M22,A:A,B:B) -> 257 | O22: =countif(M:M,A22) -> 4 | P22: =COUNTIFS(N:N,B22,J:J,">1/1/2025") -> 1 | Q22: =today()-xlookup(A22,M:M,J:J,"",0,-1) -> 320 | R22: =if(if("m"=K22,true,countif(Cull!A:A,B:B)>0),"X","") -> #REF! | W22: x | Z22: x | AA22: v | AE22: 118 | AF22: f | AI22: =IF(K22=AF22,"","X") | AJ22: x
A23: 22 | B23: 000010 | C23: 3 | D23: 10 | H23: 45801 | J23: 43547 | K23: f | L23: 6 | M23: 1 | N23: =xlookup(M23,A:A,B:B) -> 257 | O23: =countif(M:M,A23) -> 6 | P23: =COUNTIFS(N:N,B23,J:J,">1/1/2025") -> 1 | Q23: =today()-xlookup(A23,M:M,J:J,"",0,-1) -> 317 | R23: =if(if("m"=K23,true,countif(Cull!A:A,B:B)>0),"X","") -> #REF! | W23: x | Z23: x | AA23: v | AE23: 118 | AF23: f | AI23: =IF(K23=AF23,"","X") | AJ23: x
A24: 23 | B24: 000014 | C24: 3 | D24: 14 | H24: 45801 | J24: 43547 | K24: f | L24: 6 | M24: 1 | N24: =xlookup(M24,A:A,B:B) -> 257 | O24: =countif(M:M,A24) -> 9 | P24: =COUNTIFS(N:N,B24,J:J,">1/1/2025") -> 1 | Q24: =today()-xlookup(A24,M:M,J:J,"",0,-1) -> 339 | R24: =if(if("m"=K24,true,countif(Cull!A:A,B:B)>0),"X","") -> #REF! | W24: x | Z24: x | AA24: v | AJ24: x
A25: 24 | B25: 1013 | D25: 19? | H25: 43893 | J25: 43605 | K25: f | L25: 6 | M25: 12 | N25: =xlookup(M25,A:A,B:B) -> 000018 | O25: =countif(M:M,A25) -> 0 | P25: =COUNTIFS(N:N,B25,J:J,">1/1/2025") -> 0 | Q25: =today()-xlookup(A25,M:M,J:J,"",0,-1) -> 46012 | R25: =if("m"=K25,"X",if(or(countif(Cull!A:A,B:B)>0,"X"= XLOOKUP(M:M,A:A,R:R)),"X","")) -> #REF! | S25: dark brown | AB25: May be mixed up with 30 | AC25: never thrived
A26: 25 | B26: 26 | C26: Jester-5 | E26: 26 | F26: 43617 | G26: 200 | H26: 44520 | I26: 187 | J26: 43603 | K26: f | N26: =xlookup(M26,A:A,B:B) -> #N/A | O26: =countif(M:M,A26) -> 5 | P26: =COUNTIFS(N:N,B26,J:J,">1/1/2025") -> 0 | Q26: =today()-xlookup(A26,M:M,J:J,"",0,-1) -> 1497 | R26: =if("m"=K26,"X",if(or(countif(Cull!A:A,B:B)>0,"X"= XLOOKUP(M:M,A:A,R:R)),"X","")) -> #REF! | S26: mastitis | AH26: Janes
A27: 26 | B27: 27 | C27: Jester-5 | D27: 1268 | E27: 27 | F27: 43617 | G27: 200 | H27: 45450 | J27: 43603 | K27: f | N27: =xlookup(M27,A:A,B:B) -> #N/A | O27: =countif(M:M,A27) -> 6 | P27: =COUNTIFS(N:N,B27,J:J,">1/1/2025") -> 0 | Q27: =today()-xlookup(A27,M:M,J:J,"",0,-1) -> 1519 | R27: =if("m"=K27,"X",if(or(countif(Cull!A:A,B:B)>0,"X"= XLOOKUP(M:M,A:A,R:R)),"X","")) -> #REF! | S27: missing tag | AE27: 162 | AJ27: x
A28: 27 | B28: 52 | C28: Jester-5 | E28: 52 | F28: 43617 | G28: 200 | H28: 44568 | J28: 43603 | K28: f | N28: =xlookup(M28,A:A,B:B) -> #N/A | O28: =countif(M:M,A28) -> 6 | P28: =COUNTIFS(N:N,B28,J:J,">1/1/2025") -> 0 | Q28: =today()-xlookup(A28,M:M,J:J,"",0,-1) -> 1520 | R28: =if("m"=K28,"X",if(or(countif(Cull!A:A,B:B)>0,"X"= XLOOKUP(M:M,A:A,R:R)),"X","")) -> #REF! | S28: Dorper | AJ28: x
A29: 28 | B29: 32 | C29: Jester-5 | D29: 1182 | E29: 32 | F29: 43617 | G29: 200 | H29: 45450 | J29: 43603 | K29: f | N29: =xlookup(M29,A:A,B:B) -> #N/A | O29: =countif(M:M,A29) -> 13 | P29: =COUNTIFS(N:N,B29,J:J,">1/1/2025") -> 0 | Q29: =today()-xlookup(A29,M:M,J:J,"",0,-1) -> 708 | R29: =if("m"=K29,"X",if(or(countif(Cull!A:A,B:B)>0,"X"= XLOOKUP(M:M,A:A,R:R)),"X","")) -> #REF! | S29: low milk? Not motherly. | AA29: c | AJ29: x
A30: 29 | B30: 30 | C30: Jester-5 | D30: 1267 | E30: 30 | F30: 43617 | G30: 200 | H30: 45450 | J30: 43603 | K30: f | N30: =xlookup(M30,A:A,B:B) -> #N/A | O30: =countif(M:M,A30) -> 8 | P30: =COUNTIFS(N:N,B30,J:J,">1/1/2025") -> 0 | Q30: =today()-xlookup(A30,M:M,J:J,"",0,-1) -> 708 | R30: =if("m"=K30,"X",if(or(countif(Cull!A:A,B:B)>0,"X"= XLOOKUP(M:M,A:A,R:R)),"X","")) -> #REF! | S30: 12/2020 sore foot | AA30: v | AJ30: x
A31: 30 | B31: 1019 | D31: 19? | F31: 43669 | H31: 44100 | I31: =1984/15 -> 132.26667 | J31: 43669 | K31: f | L31: 6 | M31: 4 | N31: =xlookup(M31,A:A,B:B) -> 000002 | O31: =countif(M:M,A31) -> 0 | P31: =COUNTIFS(N:N,B31,J:J,">1/1/2025") -> 0 | Q31: =today()-xlookup(A31,M:M,J:J,"",0,-1) -> 46012 | R31: =if("m"=K31,"X",if(or(countif(Cull!A:A,B:B)>0,"X"= XLOOKUP(M:M,A:A,R:R)),"X","")) -> #REF! | AB31: May be mixed up with 24
A32: 31 | B32: 1001 | C32: 4 | H32: 43892 | J32: 43830 | K32: m | L32: 20 | M32: 25 | N32: =xlookup(M32,A:A,B:B) -> 26 | O32: =countif(M:M,A32) -> 0 | P32: =COUNTIFS(N:N,B32,J:J,">1/1/2025") -> 0 | Q32: =today()-xlookup(A32,M:M,J:J,"",0,-1) -> 46012 | R32: =if(if("m"=K32,true,countif(Cull!A:A,B:B)>0),"X","") -> X | S32: solid white | AB32: "stupid"
A33: 32 | B33: 1005 | C33: 4 | D33: Carson | E33: 68024 | H33: 44100 | I33: =1984/15 -> 132.26667 | J33: 43831 | K33: m | L33: 20 | M33: 28 | N33: =xlookup(M33,A:A,B:B) -> 32 | O33: =countif(M:M,A33) -> 0 | P33: =COUNTIFS(N:N,B33,J:J,">1/1/2025") -> 0 | Q33: =today()-xlookup(A33,M:M,J:J,"",0,-1) -> 46012 | R33: {=if("m"=K33,"X",if(or(countif(Cull!A:A,B:B)>0,"X"= XLOOKUP(M:M,A:A,R:R)),"X",""))} -> X | S33: tan collar
A34: 33 | B34: 1118 | C34: 4 | D34: bella | E34: 68015 | J34: 43831 | K34: f | L34: 20 | M34: 28 | N34: =xlookup(M34,A:A,B:B) -> 32 | O34: =countif(M:M,A34) -> 7 | P34: =COUNTIFS(N:N,B34,J:J,">1/1/2025") -> 2 | Q34: =today()-xlookup(A34,M:M,J:J,"",0,-1) -> 318 | R34: =if(if("m"=K34,true,countif(Cull!A:A,B:B)>0),"X","") -> #REF! | S34: solid white | T34: x | W34: x | Z34: x | AA34: v | AE34: 92 | AF34: f | AG34: was 1004 | AI34: =IF(K34=AF34,"","X") | AJ34: x
A35: 34 | B35: 1376 | C35: 4 | D35: bella | E35: 68005 | J35: 43835 | K35: f | L35: 20 | M35: 26 | N35: =xlookup(M35,A:A,B:B) -> 27 | O35: =countif(M:M,A35) -> 4 | P35: =COUNTIFS(N:N,B35,J:J,">1/1/2025") -> 0 | Q35: =today()-xlookup(A35,M:M,J:J,"",0,-1) -> 46012 | R35: =if(if("m"=K35,true,countif(Cull!A:A,B:B)>0),"X","") -> #REF! | S35: blotchy white, was 1121 | T35: new tag 1376? | AE35: 90 | AF35: f | AG35: was 1060 | AI35: =IF(K35=AF35,"","X") | AJ35: x
A36: 35 | B36: 1009 | C36: 4 | H36: 44100 | I36: =1984/15 -> 132.26667 | J36: 43835 | K36: m | L36: 20 | M36: 26 | N36: =xlookup(M36,A:A,B:B) -> 27 | O36: =countif(M:M,A36) -> 0 | P36: =COUNTIFS(N:N,B36,J:J,">1/1/2025") -> 0 | Q36: =today()-xlookup(A36,M:M,J:J,"",0,-1) -> 46012 | R36: =if("m"=K36,"X",if(or(countif(Cull!A:A,B:B)>0,"X"= XLOOKUP(M:M,A:A,R:R)),"X","")) -> X | S36: cinnamon
A37: 36 | B37: 1002 | C37: 4 | H37: 44100 | I37: =1984/15 -> 132.26667 | J37: 43849 | K37: m | L37: 20 | M37: 29 | N37: =xlookup(M37,A:A,B:B) -> 30 | O37: =countif(M:M,A37) -> 0 | P37: =COUNTIFS(N:N,B37,J:J,">1/1/2025") -> 0 | Q37: =today()-xlookup(A37,M:M,J:J,"",0,-1) -> 46012 | R37: =if("m"=K37,"X",if(or(countif(Cull!A:A,B:B)>0,"X"= XLOOKUP(M:M,A:A,R:R)),"X","")) -> X
A38: 37 | B38: 1003 | C38: 4 | H38: 44100 | I38: =1984/15 -> 132.26667 | J38: 43849 | K38: m | L38: 20 | M38: 29 | N38: =xlookup(M38,A:A,B:B) -> 30 | O38: =countif(M:M,A38) -> 0 | P38: =COUNTIFS(N:N,B38,J:J,">1/1/2025") -> 0 | Q38: =today()-xlookup(A38,M:M,J:J,"",0,-1) -> 46012 | R38: =if("m"=K38,"X",if(or(countif(Cull!A:A,B:B)>0,"X"= XLOOKUP(M:M,A:A,R:R)),"X","")) -> X
A39: 38 | B39: 1011 | C39: 4 | H39: 44100 | I39: =1984/15 -> 132.26667 | J39: 43851 | K39: m | L39: 20 | M39: 10 | N39: =xlookup(M39,A:A,B:B) -> 1006 | O39: =countif(M:M,A39) -> 0 | P39: =COUNTIFS(N:N,B39,J:J,">1/1/2025") -> 0 | Q39: =today()-xlookup(A39,M:M,J:J,"",0,-1) -> 46012 | R39: =if("m"=K39,"X",if(or(countif(Cull!A:A,B:B)>0,"X"= XLOOKUP(M:M,A:A,R:R)),"X","")) -> X
A40: 39 | B40: 1049 | C40: 4 | J40: 43851 | K40: f | L40: 20 | M40: 9 | N40: =xlookup(M40,A:A,B:B) -> 000017 | O40: =countif(M:M,A40) -> 1 | P40: =COUNTIFS(N:N,B40,J:J,">1/1/2025") -> 0 | Q40: =today()-xlookup(A40,M:M,J:J,"",0,-1) -> 1730 | R40: =if(if("m"=K40,true,countif(Cull!A:A,B:B)>0),"X","") -> #REF! | AE40: 118 | AF40: f | AI40: =IF(K40=AF40,"","X") | AJ40: x
...
